<?xml version="1.0"?>
<robot name="single_motor" xmlns:xacro="http://www.ros.org/wiki/xacro">

    <material name="blue">
        <color rgba="0 0 0.8 1" />
    </material>

    <material name="red">
        <color rgba="0.8 0 0 1" />
    </material>

    <link name="base_footprint" />

    <link name="base_link" >
        <visual>
            <geometry>
                <box size="0.4 0.2 0.1" />
            </geometry>    
            <origin xyz="0 0 0.05" rpy="0 0 0" />
            <material name="blue" />
        </visual>
    </link>

    <link name="motor_link">
        <visual>
            <geometry>
                <cylinder radius="0.05" length="0.04" />
            </geometry>    
            <origin xyz="0 0 0.02" rpy="0 0 0" />
            <material name="red" />
        </visual>
    </link>

    <joint name="footprint_base_joint" type="fixed">
        <parent link="base_footprint" />
        <child link="base_link" />
        <origin xyz="0 0 0" rpy="0 0 0" />
    </joint>

    <joint name="base_motor_joint" type="continuous">
        <parent link="base_link" />
        <child link="motor_link" />
        <origin xyz="0 0 0.1" rpy="0 0 0" />
        <axis xyz="0 0 1" />
    </joint>

    <ros2_control name="motor_hardware" type="actuator">
        <hardware>
            <plugin>motor_control/MotorHardwareInterface</plugin>  <!-- name of th class in .hpp file-->
        </hardware>

        <joint name="base_motor_joint">
            <command_interface name="velocity" />
            <state_interface name="position" />
            <state_interface name="velocity" />
        </joint>
    </ros2_control>

</robot>